Workbook

Sheet Notas
A2: Se procesaron los datos analizando la matriz detectada. Las celdas vacías por inconvergencia fueron filtradas individualmente.
A3: PRECISIÓN NUMÉRICA: Cálculo flotante de 64 bits sin redondeos en memoria.

Sheet Resultados_Simulacion
A1: Re | B1: Posición de trip (x/c) | C1: Cl_max | D1: alfa @ Cl_max | E1: Cd @ Cl_max | F1: (Cl/Cd)_max | G1: alfa @ (Cl/Cd)_max | H1: Cd @ (Cl/Cd)_max | I1: Cd @ Cl=0.50 | J1: alfa @ Cl=0.50 | K1: Encabezado original
A2: 66000 | B2: Libre | C2: 1.407762 | D2: 9.75 | E2: 0.04301454 | F2: 40.039575 | G2: 5.75 | H2: 0.02934674 | I2: 0.028441567 | J2: -0.083706888 | K2: T1_Re0.066_M0.00_N9.0
A3: 66000 | B3: 5% | C3: 1.205866 | D3: 11 | E3: 0.06422879 | F3: 32.947093 | G3: 5 | H3: 0.02901286 | I3: 0.021257213 | J3: -0.19164924 | K3: T1_Re0.066_M0.00_N9.0_XtrTop 5%
A4: 66000 | B4: 10% | C4: 1.322555 | D4: 12.5 | E4: 0.07108319 | F4: 34.545268 | G4: 5.25 | H4: 0.02852078 | I4: 0.020862962 | J4: -0.22195298 | K4: T1_Re0.066_M0.00_N9.0_XtrTop10%
A5: 66000 | B5: 15% | C5: 1.385008 | D5: 11 | E5: 0.05066762 | F5: 36.30487 | G5: 5.5 | H5: 0.0280047 | I5: 0.020415983 | J5: -0.25844766 | K5: T1_Re0.066_M0.00_N9.0_XtrTop15%
A6: 66000 | B6: 20% | C6: 1.407762 | D6: 9.75 | E6: 0.04301458 | F6: 37.944652 | G6: 5.75 | H6: 0.02766548 | I6: 0.019959565 | J6: -0.29808396 | K6: T1_Re0.066_M0.00_N9.0_XtrTop20%
A7: 66000 | B7: 25% | C7: 1.407762 | D7: 9.75 | E7: 0.04301454 | F7: 39.221841 | G7: 6 | H7: 0.02760977 | I7: 0.01956056 | J7: -0.33481511 | K7: T1_Re0.066_M0.00_N9.0_XtrTop25%
A8: 66000 | B8: 30% | C8: 1.407762 | D8: 9.75 | E8: 0.04301454 | F8: 40.98146 | G8: 6.5 | H8: 0.02812096 | I8: 0.019090317 | J8: -0.38098997 | K8: T1_Re0.066_M0.00_N9.0_XtrTop30%
A9: 66000 | B9: 35% | C9: 1.407762 | D9: 9.75 | E9: 0.04301454 | F9: 42.672214 | G9: 6 | H9: 0.02663035 | I9: 0.018519004 | J9: -0.4435362 | K9: T1_Re0.066_M0.00_N9.0_XtrTop35%
A10: 66000 | B10: 38% | C10: 1.407762 | D10: 9.75 | E10: 0.04301454 | F10: 43.243985 | G10: 5.75 | H10: 0.02604198 | I10: 0.01825552 | J10: -0.47571351 | K10: T1_Re0.066_M0.00_N9.0_XtrTop38%
A11: 66000 | B11: 40% | C11: 1.407762 | D11: 9.75 | E11: 0.04301454 | F11: 43.562058 | G11: 5.25 | H11: 0.02490369 | I11: 0.018024199 | J11: -0.5060835 | K11: T1_Re0.066_M0.00_N9.0_XtrTop40%
A12: 66000 | B12: 45% | C12: 1.407762 | D12: 9.75 | E12: 0.04301454 | F12: 43.723216 | G12: 4.5 | H12: 0.02346289 | I12: 0.017659925 | J12: -0.55879539 | K12: T1_Re0.066_M0.00_N9.0_XtrTop45%
A13: 66000 | B13: 48% | C13: 1.407762 | D13: 9.75 | E13: 0.04301454 | F13: 43.559843 | G13: 4.25 | H13: 0.02316535 | I13: 0.01751122 | J13: -0.58259267 | K13: T1_Re0.066_M0.00_N9.0_XtrTop48%
... A210: 231000 | B210: 70% | C210: 1.399889 | D210: 10.25 | E210: 0.03224139 | F210: 77.350442 | G210: 2.25 | H210: 0.01117473 | I210: 0.0091253865 | J210: -1.4355249 | K210: T1_Re0.231_M0.00_N9.0_XtrTop70%

Sheet Variación Porcentual frente a L
B2: Re= 119K
B3: Posición de Trip (x/c) | C3: Ángulo de Ataque @ CL=0,50 | D3: CD_@CL=0,50 (Interpolado) | E3: Variación Porcentual frente a Libre (%∆ CD) | F3: Evaluación de la Continuidad Física
B4: Libre (Línea Base) | C4: =Resultados_Simulacion!J97 -> -1.2839015 | D4: =Resultados_Simulacion!I97 -> 0.015326279 | E4: 0%(referencia) | F4: Caso base de referencia (transición natural)
B5: 0.3 | C5: =Resultados_Simulacion!J103 -> -0.77704343 | D5: =Resultados_Simulacion!I103 -> 0.014674283 | E5: =(D5-D4)/D4 -> -0.042541066 | F5: Reducción progresiva de CD por control de la burbuja
B6: 0.38 | C6: =Resultados_Simulacion!J105 -> -0.86703949 | D6: =Resultados_Simulacion!I105 -> 0.013935126 | E6: =(D6-D4)/D4 -> -0.090769122 | F6: Comportamiento suave y continuo sin artefactos
B7: 0.45 | C7: =Resultados_Simulacion!J107 -> -0.94953221 | D7: =Resultados_Simulacion!I107 -> 0.01336013 | E7: =(D7-D4)/D4 -> -0.12828613 | F7: Tendencia monótona previsible en el tramo lineal

Sheet Variacion_vs_Libre
A1: Re | B1: Posición de trip (x/c) | C1: Cl_max | D1: % var. Cl_max | E1: Cd @ Cl_max | F1: % var. Cd @ Cl_max | G1: (Cl/Cd)_max | H1: % var. (Cl/Cd)_max | I1: Cd @ (Cl/Cd)_max | J1: % var. Cd @ (Cl/Cd)_max | K1: Cd @ Cl=0.50 | L1: % var. Cd @ Cl=0.50
A2: 66000 | B2: Libre | C2: =Resultados_Simulacion!C2 -> 1.407762 | D2: =(C2-Resultados_Simulacion!C2)/Resultados_Simulacion!C2 -> 0 | E2: =Resultados_Simulacion!E2 -> 0.04301454 | F2: =(E2-Resultados_Simulacion!E2)/Resultados_Simulacion!E2 -> 0 | G2: =Resultados_Simulacion!F2 -> 40.039575 | H2: =(G2-Resultados_Simulacion!F2)/Resultados_Simulacion!F2 -> 0 | I2: =Resultados_Simulacion!H2 -> 0.02934674 | J2: =(I2-Resultados_Simulacion!H2)/Resultados_Simulacion!H2 -> 0 | K2: =Resultados_Simulacion!I2 -> 0.028441567 | L2: =(K2-Resultados_Simulacion!I2)/Resultados_Simulacion!I2 -> 0
A3: 66000 | B3: 5% | C3: =Resultados_Simulacion!C3 -> 1.205866 | D3: =(C3-Resultados_Simulacion!C2)/Resultados_Simulacion!C2 -> -0.14341629 | E3: =Resultados_Simulacion!E3 -> 0.06422879 | F3: =(E3-Resultados_Simulacion!E2)/Resultados_Simulacion!E2 -> 0.49318788 | G3: =Resultados_Simulacion!F3 -> 32.947093 | H3: =(G3-Resultados_Simulacion!F2)/Resultados_Simulacion!F2 -> -0.17713679 | I3: =Resultados_Simulacion!H3 -> 0.02901286 | J3: =(I3-Resultados_Simulacion!H2)/Resultados_Simulacion!H2 -> -0.011377073 | K3: =Resultados_Simulacion!I3 -> 0.021257213 | L3: =(K3-Resultados_Simulacion!I2)/Resultados_Simulacion!I2 -> -0.2526005
A4: 66000 | B4: 10% | C4: =Resultados_Simulacion!C4 -> 1.322555 | D4: =(C4-Resultados_Simulacion!C2)/Resultados_Simulacion!C2 -> -0.060526566 | E4: =Resultados_Simulacion!E4 -> 0.07108319 | F4: =(E4-Resultados_Simulacion!E2)/Resultados_Simulacion!E2 -> 0.65253865 | G4: =Resultados_Simulacion!F4 -> 34.545268 | H4: =(G4-Resultados_Simulacion!F2)/Resultados_Simulacion!F2 -> -0.1372219 | I4: =Resultados_Simulacion!H4 -> 0.02852078 | J4: =(I4-Resultados_Simulacion!H2)/Resultados_Simulacion!H2 -> -0.028144864 | K4: =Resultados_Simulacion!I4 -> 0.020862962 | L4: =(K4-Resultados_Simulacion!I2)/Resultados_Simulacion!I2 -> -0.2664623
A5: 66000 | B5: 15% | C5: =Resultados_Simulacion!C5 -> 1.385008 | D5: =(C5-Resultados_Simulacion!C2)/Resultados_Simulacion!C2 -> -0.016163244 | E5: =Resultados_Simulacion!E5 -> 0.05066762 | F5: =(E5-Resultados_Simulacion!E2)/Resultados_Simulacion!E2 -> 0.17791844 | G5: =Resultados_Simulacion!F5 -> 36.30487 | H5: =(G5-Resultados_Simulacion!F2)/Resultados_Simulacion!F2 -> -0.093275337 | I5: =Resultados_Simulacion!H5 -> 0.0280047 | J5: =(I5-Resultados_Simulacion!H2)/Resultados_Simulacion!H2 -> -0.045730463 | K5: =Resultados_Simulacion!I5 -> 0.020415983 | L5: =(K5-Resultados_Simulacion!I2)/Resultados_Simulacion!I2 -> -0.282178
A6: 66000 | B6: 20% | C6: =Resultados_Simulacion!C6 -> 1.407762 | D6: =(C6-Resultados_Simulacion!C2)/Resultados_Simulacion!C2 -> 0 | E6: =Resultados_Simulacion!E6 -> 0.04301458 | F6: =(E6-Resultados_Simulacion!E2)/Resultados_Simulacion!E2 -> 9.2991812e-07 | G6: =Resultados_Simulacion!F6 -> 37.944652 | H6: =(G6-Resultados_Simulacion!F2)/Resultados_Simulacion!F2 -> -0.052321322 | I6: =Resultados_Simulacion!H6 -> 0.02766548 | J6: =(I6-Resultados_Simulacion!H2)/Resultados_Simulacion!H2 -> -0.057289498 | K6: =Resultados_Simulacion!I6 -> 0.019959565 | L6: =(K6-Resultados_Simulacion!I2)/Resultados_Simulacion!I2 -> -0.29822557
A7: 66000 | B7: 25% | C7: =Resultados_Simulacion!C7 -> 1.407762 | D7: =(C7-Resultados_Simulacion!C2)/Resultados_Simulacion!C2 -> 0 | E7: =Resultados_Simulacion!E7 -> 0.04301454 | F7: =(E7-Resultados_Simulacion!E2)/Resultados_Simulacion!E2 -> 0 | G7: =Resultados_Simulacion!F7 -> 39.221841 | H7: =(G7-Resultados_Simulacion!F2)/Resultados_Simulacion!F2 -> -0.020423154 | I7: =Resultados_Simulacion!H7 -> 0.02760977 | J7: =(I7-Resultados_Simulacion!H2)/Resultados_Simulacion!H2 -> -0.059187835 | K7: =Resultados_Simulacion!I7 -> 0.01956056 | L7: =(K7-Resultados_Simulacion!I2)/Resultados_Simulacion!I2 -> -0.3122545
A8: 66000 | B8: 30% | C8: =Resultados_Simulacion!C8 -> 1.407762 | D8: =(C8-Resultados_Simulacion!C2)/Resultados_Simulacion!C2 -> 0 | E8: =Resultados_Simulacion!E8 -> 0.04301454 | F8: =(E8-Resultados_Simulacion!E2)/Resultados_Simulacion!E2 -> 0 | G8: =Resultados_Simulacion!F8 -> 40.98146 | H8: =(G8-Resultados_Simulacion!F2)/Resultados_Simulacion!F2 -> 0.023523851 | I8: =Resultados_Simulacion!H8 -> 0.02812096 | J8: =(I8-Resultados_Simulacion!H2)/Resultados_Simulacion!H2 -> -0.041768864 | K8: =Resultados_Simulacion!I8 -> 0.019090317 | L8: =(K8-Resultados_Simulacion!I2)/Resultados_Simulacion!I2 -> -0.32878816
A9: 66000 | B9: 35% | C9: =Resultados_Simulacion!C9 -> 1.407762 | D9: =(C9-Resultados_Simulacion!C2)/Resultados_Simulacion!C2 -> 0 | E9: =Resultados_Simulacion!E9 -> 0.04301454 | F9: =(E9-Resultados_Simulacion!E2)/Resultados_Simulacion!E2 -> 0 | G9: =Resultados_Simulacion!F9 -> 42.672214 | H9: =(G9-Resultados_Simulacion!F2)/Resultados_Simulacion!F2 -> 0.065750926 | I9: =Resultados_Simulacion!H9 -> 0.02663035 | J9: =(I9-Resultados_Simulacion!H2)/Resultados_Simulacion!H2 -> -0.0925619 | K9: =Resultados_Simulacion!I9 -> 0.018519004 | L9: =(K9-Resultados_Simulacion!I2)/Resultados_Simulacion!I2 -> -0.34887539
A10: 66000 | B10: 38% | C10: =Resultados_Simulacion!C10 -> 1.407762 | D10: =(C10-Resultados_Simulacion!C2)/Resultados_Simulacion!C2 -> 0 | E10: =Resultados_Simulacion!E10 -> 0.04301454 | F10: =(E10-Resultados_Simulacion!E2)/Resultados_Simulacion!E2 -> 0 | G10: =Resultados_Simulacion!F10 -> 43.243985 | H10: =(G10-Resultados_Simulacion!F2)/Resultados_Simulacion!F2 -> 0.080031074 | I10: =Resultados_Simulacion!H10 -> 0.02604198 | J10: =(I10-Resultados_Simulacion!H2)/Resultados_Simulacion!H2 -> -0.1126108 | K10: =Resultados_Simulacion!I10 -> 0.01825552 | L10: =(K10-Resultados_Simulacion!I2)/Resultados_Simulacion!I2 -> -0.35813945
A11: 66000 | B11: 40% | C11: =Resultados_Simulacion!C11 -> 1.407762 | D11: =(C11-Resultados_Simulacion!C2)/Resultados_Simulacion!C2 -> 0 | E11: =Resultados_Simulacion!E11 -> 0.04301454 | F11: =(E11-Resultados_Simulacion!E2)/Resultados_Simulacion!E2 -> 0 | G11: =Resultados_Simulacion!F11 -> 43.562058 | H11: =(G11-Resultados_Simulacion!F2)/Resultados_Simulacion!F2 -> 0.087975044 | I11: =Resultados_Simulacion!H11 -> 0.02490369 | J11: =(I11-Resultados_Simulacion!H2)/Resultados_Simulacion!H2 -> -0.15139842 | K11: =Resultados_Simulacion!I11 -> 0.018024199 | L11: =(K11-Resultados_Simulacion!I2)/Resultados_Simulacion!I2 -> -0.36627267
A12: 66000 | B12: 45% | C12: =Resultados_Simulacion!C12 -> 1.407762 | D12: =(C12-Resultados_Simulacion!C2)/Resultados_Simulacion!C2 -> 0 | E12: =Resultados_Simulacion!E12 -> 0.04301454 | F12: =(E12-Resultados_Simulacion!E2)/Resultados_Simulacion!E2 -> 0 | G12: =Resultados_Simulacion!F12 -> 43.723216 | H12: =(G12-Resultados_Simulacion!F2)/Resultados_Simulacion!F2 -> 0.091999992 | I12: =Resultados_Simulacion!H12 -> 0.02346289 | J12: =(I12-Resultados_Simulacion!H2)/Resultados_Simulacion!H2 -> -0.20049416 | K12: =Resultados_Simulacion!I12 -> 0.017659925 | L12: =(K12-Resultados_Simulacion!I2)/Resultados_Simulacion!I2 -> -0.37908046
A13: 66000 | B13: 48% | C13: =Resultados_Simulacion!C13 -> 1.407762 | D13: =(C13-Resultados_Simulacion!C2)/Resultados_Simulacion!C2 -> 0 | E13: =Resultados_Simulacion!E13 -> 0.04301454 | F13: =(E13-Resultados_Simulacion!E2)/Resultados_Simulacion!E2 -> 0 | G13: =Resultados_Simulacion!F13 -> 43.559843 | H13: =(G13-Resultados_Simulacion!F2)/Resultados_Simulacion!F2 -> 0.087919702 | I13: =Resultados_Simulacion!H13 -> 0.02316535 | J13: =(I13-Resultados_Simulacion!H2)/Resultados_Simulacion!H2 -> -0.21063294 | K13: =Resultados_Simulacion!I13 -> 0.01751122 | L13: =(K13-Resultados_Simulacion!I2)/Resultados_Simulacion!I2 -> -0.38430891
A14: 66000 | B14: 50% | C14: =Resultados_Simulacion!C14 -> 1.407762 | D14: =(C14-Resultados_Simulacion!C2)/Resultados_Simulacion!C2 -> 0 | E14: =Resultados_Simulacion!E14 -> 0.04301454 | F14: =(E14-Resultados_Simulacion!E2)/Resultados_Simulacion!E2 -> 0 | G14: =Resultados_Simulacion!F14 -> 43.27614 | H14: =(G14-Resultados_Simulacion!F2)/Resultados_Simulacion!F2 -> 0.080834141 | I14: =Resultados_Simulacion!H14 -> 0.02219771 | J14: =(I14-Resultados_Simulacion!H2)/Resultados_Simulacion!H2 -> -0.24360559 | K14: =Resultados_Simulacion!I14 -> 0.017381612 | L14: =(K14-Resultados_Simulacion!I2)/Resultados_Simulacion!I2 -> -0.38886589
A15: 66000 | B15: 55% | C15: =Resultados_Simulacion!C15 -> 1.407762 | D15: =(C15-Resultados_Simulacion!C2)/Resultados_Simulacion!C2 -> 0 | E15: =Resultados_Simulacion!E15 -> 0.04301454 | F15: =(E15-Resultados_Simulacion!E2)/Resultados_Simulacion!E2 -> 0 | G15: =Resultados_Simulacion!F15 -> 42.136725 | H15: =(G15-Resultados_Simulacion!F2)/Resultados_Simulacion!F2 -> 0.052376938 | I15: =Resultados_Simulacion!H15 -> 0.02185592 | J15: =(I15-Resultados_Simulacion!H2)/Resultados_Simulacion!H2 -> -0.2552522 | K15: =Resultados_Simulacion!I15 -> 0.017189425 | L15: =(K15-Resultados_Simulacion!I2)/Resultados_Simulacion!I2 -> -0.39562313
A16: 66000 | B16: 57% | C16: =Resultados_Simulacion!C16 -> 1.407762 | D16: =(C16-Resultados_Simulacion!C2)/Resultados_Simulacion!C2 -> 0 | E16: =Resultados_Simulacion!E16 -> 0.04301454 | F16: =(E16-Resultados_Simulacion!E2)/Resultados_Simulacion!E2 -> 0 | G16: =Resultados_Simulacion!F16 -> 41.171515 | H16: =(G16-Resultados_Simulacion!F2)/Resultados_Simulacion!F2 -> 0.028270536 | I16: =Resultados_Simulacion!H16 -> 0.02108517 | J16: =(I16-Resultados_Simulacion!H2)/Resultados_Simulacion!H2 -> -0.28151577 | K16: =Resultados_Simulacion!I16 -> 0.017137566 | L16: =(K16-Resultados_Simulacion!I2)/Resultados_Simulacion!I2 -> -0.39744651
A17: 66000 | B17: 60% | C17: =Resultados_Simulacion!C17 -> 1.407762 | D17: =(C17-Resultados_Simulacion!C2)/Resultados_Simulacion!C2 -> 0 | E17: =Resultados_Simulacion!E17 -> 0.04301454 | F17: =(E17-Resultados_Simulacion!E2)/Resultados_Simulacion!E2 -> 0 | G17: =Resultados_Simulacion!F17 -> 40.12735 | H17: =(G17-Resultados_Simulacion!F2)/Resultados_Simulacion!F2 -> 0.0021921997 | I17: =Resultados_Simulacion!H17 -> 0.02108601 | J17: =(I17-Resultados_Simulacion!H2)/Resultados_Simulacion!H2 -> -0.28148714 | K17: =Resultados_Simulacion!I17 -> 0.017119058 | L17: =(K17-Resultados_Simulacion!I2)/Resultados_Simulacion!I2 -> -0.39809724
A18: 66000 | B18: 65% | C18: =Resultados_Simulacion!C18 -> 1.407762 | D18: =(C18-Resultados_Simulacion!C2)/Resultados_Simulacion!C2 -> 0 | E18: =Resultados_Simulacion!E18 -> 0.04301454 | F18: =(E18-Resultados_Simulacion!E2)/Resultados_Simulacion!E2 -> 0 | G18: =Resultados_Simulacion!F18 -> 40.039575 | H18: =(G18-Resultados_Simulacion!F2)/Resultados_Simulacion!F2 -> 0 | I18: =Resultados_Simulacion!H18 -> 0.02934674 | J18: =(I18-Resultados_Simulacion!H2)/Resultados_Simulacion!H2 -> 0 | K18: =Resultados_Simulacion!I18 -> 0.017205349 | L18: =(K18-Resultados_Simulacion!I2)/Resultados_Simulacion!I2 -> -0.39506324
A19: 66000 | B19: 68% | C19: =Resultados_Simulacion!C19 -> 1.407762 | D19: =(C19-Resultados_Simulacion!C2)/Resultados_Simulacion!C2 -> 0 | E19: =Resultados_Simulacion!E19 -> 0.04301454 | F19: =(E19-Resultados_Simulacion!E2)/Resultados_Simulacion!E2 -> 0 | G19: =Resultados_Simulacion!F19 -> 40.039575 | H19: =(G19-Resultados_Simulacion!F2)/Resultados_Simulacion!F2 -> 0 | I19: =Resultados_Simulacion!H19 -> 0.02934674 | J19: =(I19-Resultados_Simulacion!H2)/Resultados_Simulacion!H2 -> 0 | K19: =Resultados_Simulacion!I19 -> 0.017329521 | L19: =(K19-Resultados_Simulacion!I2)/Resultados_Simulacion!I2 -> -0.39069739
A20: 66000 | B20: 70% | C20: =Resultados_Simulacion!C20 -> 1.407762 | D20: =(C20-Resultados_Simulacion!C2)/Resultados_Simulacion!C2 -> 0 | E20: =Resultados_Simulacion!E20 -> 0.04301454 | F20: =(E20-Resultados_Simulacion!E2)/Resultados_Simulacion!E2 -> 0 | G20: =Resultados_Simulacion!F20 -> 40.039575 | H20: =(G20-Resultados_Simulacion!F2)/Resultados_Simulacion!F2 -> 0 | I20: =Resultados_Simulacion!H20 -> 0.02934674 | J20: =(I20-Resultados_Simulacion!H2)/Resultados_Simulacion!H2 -> 0 | K20: =Resultados_Simulacion!I20 -> 0.01756337 | L20: =(K20-Resultados_Simulacion!I2)/Resultados_Simulacion!I2 -> -0.38247532
A21: 73000 | B21: Libre | C21: =Resultados_Simulacion!C21 -> 1.396031 | D21: =(C21-Resultados_Simulacion!C21)/Resultados_Simulacion!C21 -> 0 | E21: =Resultados_Simulacion!E21 -> 0.04061992 | F21: =(E21-Resultados_Simulacion!E21)/Resultados_Simulacion!E21 -> 0 | G21: =Resultados_Simulacion!F21 -> 43.234172 | H21: =(G21-Resultados_Simulacion!F21)/Resultados_Simulacion!F21 -> 0 | I21: =Resultados_Simulacion!H21 -> 0.02781256 | J21: =(I21-Resultados_Simulacion!H21)/Resultados_Simulacion!H21 -> 0 | K21: =Resultados_Simulacion!I21 -> 0.025858 | L21: =(K21-Resultados_Simulacion!I21)/Resultados_Simulacion!I21 -> 0
A22: 73000 | B22: 5% | C22: =Resultados_Simulacion!C22 -> 1.232554 | D22: =(C22-Resultados_Simulacion!C21)/Resultados_Simulacion!C21 -> -0.11710127 | E22: =Resultados_Simulacion!E22 -> 0.06045188 | F22: =(E22-Resultados_Simulacion!E21)/Resultados_Simulacion!E21 -> 0.48823237 | G22: =Resultados_Simulacion!F22 -> 34.919186 | H22: =(G22-Resultados_Simulacion!F21)/Resultados_Simulacion!F21 -> -0.1923244 | I22: =Resultados_Simulacion!H22 -> 0.02780515 | J22: =(I22-Resultados_Simulacion!H21)/Resultados_Simulacion!H21 -> -0.00026642639 | K22: =Resultados_Simulacion!I22 -> 0.020358694 | L22: =(K22-Resultados_Simulacion!I21)/Resultados_Simulacion!I21 -> -0.21267328
A23: 73000 | B23: 10% | C23: =Resultados_Simulacion!C23 -> 1.322094 | D23: =(C23-Resultados_Simulacion!C21)/Resultados_Simulacion!C21 -> -0.052962291 | E23: =Resultados_Simulacion!E23 -> 0.06590917 | F23: =(E23-Resultados_Simulacion!E21)/Resultados_Simulacion!E21 -> 0.62258247 | G23: =Resultados_Simulacion!F23 -> 36.694126 | H23: =(G23-Resultados_Simulacion!F21)/Resultados_Simulacion!F21 -> -0.15127029 | I23: =Resultados_Simulacion!H23 -> 0.02727878 | J23: =(I23-Resultados_Simulacion!H21)/Resultados_Simulacion!H21 -> -0.019192048 | K23: =Resultados_Simulacion!I23 -> 0.019975364 | L23: =(K23-Resultados_Simulacion!I21)/Resultados_Simulacion!I21 -> -0.22749771
A24: 73000 | B24: 15% | C24: =Resultados_Simulacion!C24 -> 1.378072 | D24: =(C24-Resultados_Simulacion!C21)/Resultados_Simulacion!C21 -> -0.012864328 | E24: =Resultados_Simulacion!E24 -> 0.04889419 | F24: =(E24-Resultados_Simulacion!E21)/Resultados_Simulacion!E21 -> 0.20369981 | G24: =Resultados_Simulacion!F24 -> 38.619947 | H24: =(G24-Resultados_Simulacion!F21)/Resultados_Simulacion!F21 -> -0.10672634 | I24: =Resultados_Simulacion!H24 -> 0.02674144 | J24: =(I24-Resultados_Simulacion!H21)/Resultados_Simulacion!H21 -> -0.038512097 | K24: =Resultados_Simulacion!I24 -> 0.019541416 | L24: =(K24-Resultados_Simulacion!I21)/Resultados_Simulacion!I21 -> -0.24427965
A25: 73000 | B25: 20% | C25: =Resultados_Simulacion!C25 -> 1.396031 | D25: =(C25-Resultados_Simulacion!C21)/Resultados_Simulacion!C21 -> 0 | E25: =Resultados_Simulacion!E25 -> 0.04061992 | F25: =(E25-Resultados_Simulacion!E21)/Resultados_Simulacion!E21 -> 0 | G25: =Resultados_Simulacion!F25 -> 40.392532 | H25: =(G25-Resultados_Simulacion!F21)/Resultados_Simulacion!F21 -> -0.0657267 | I25: =Resultados_Simulacion!H25 -> 0.02687472 | J25: =(I25-Resultados_Simulacion!H21)/Resultados_Simulacion!H21 -> -0.033720017 | K25: =Resultados_Simulacion!I25 -> 0.019100652 | L25: =(K25-Resultados_Simulacion!I21)/Resultados_Simulacion!I21 -> -0.26132524
A26: 73000 | B26: 25% | C26: =Resultados_Simulacion!C26 -> 1.396031 | D26: =(C26-Resultados_Simulacion!C21)/Resultados_Simulacion!C21 -> 0 | E26: =Resultados_Simulacion!E26 -> 0.04061992 | F26: =(E26-Resultados_Simulacion!E21)/Resultados_Simulacion!E21 -> 0 | G26: =Resultados_Simulacion!F26 -> 41.74387 | H26: =(G26-Resultados_Simulacion!F21)/Resultados_Simulacion!F21 -> -0.034470462 | I26: =Resultados_Simulacion!H26 -> 0.0268231 | J26: =(I26-Resultados_Simulacion!H21)/Resultados_Simulacion!H21 -> -0.035576013 | K26: =Resultados_Simulacion!I26 -> 0.018711268 | L26: =(K26-Resultados_Simulacion!I21)/Resultados_Simulacion!I21 -> -0.27638378
A27: 73000 | B27: 30% | C27: =Resultados_Simulacion!C27 -> 1.396031 | D27: =(C27-Resultados_Simulacion!C21)/Resultados_Simulacion!C21 -> 0 | E27: =Resultados_Simulacion!E27 -> 0.04061992 | F27: =(E27-Resultados_Simulacion!E21)/Resultados_Simulacion!E21 -> 0 | G27: =Resultados_Simulacion!F27 -> 43.458622 | H27: =(G27-Resultados_Simulacion!F21)/Resultados_Simulacion!F21 -> 0.0051914997 | I27: =Resultados_Simulacion!H27 -> 0.02685237 | J27: =(I27-Resultados_Simulacion!H21)/Resultados_Simulacion!H21 -> -0.034523611 | K27: =Resultados_Simulacion!I27 -> 0.018252918 | L27: =(K27-Resultados_Simulacion!I21)/Resultados_Simulacion!I21 -> -0.29410944
A28: 73000 | B28: 35% | C28: =Resultados_Simulacion!C28 -> 1.396031 | D28: =(C28-Resultados_Simulacion!C21)/Resultados_Simulacion!C21 -> 0 | E28: =Resultados_Simulacion!E28 -> 0.04061992 | F28: =(E28-Resultados_Simulacion!E21)/Resultados_Simulacion!E21 -> 0 | G28: =Resultados_Simulacion!F28 -> 45.103905 | H28: =(G28-Resultados_Simulacion!F21)/Resultados_Simulacion!F21 -> 0.043246639 | I28: =Resultados_Simulacion!H28 -> 0.02547724 | J28: =(I28-Resultados_Simulacion!H21)/Resultados_Simulacion!H21 -> -0.083966381 | K28: =Resultados_Simulacion!I28 -> 0.017698904 | L28: =(K28-Resultados_Simulacion!I21)/Resultados_Simulacion!I21 -> -0.31553467
A29: 73000 | B29: 38% | C29: =Resultados_Simulacion!C29 -> 1.396031 | D29: =(C29-Resultados_Simulacion!C21)/Resultados_Simulacion!C21 -> 0 | E29: =Resultados_Simulacion!E29 -> 0.04061992 | F29: =(E29-Resultados_Simulacion!E21)/Resultados_Simulacion!E21 -> 0 | G29: =Resultados_Simulacion!F29 -> 45.672292 | H29: =(G29-Resultados_Simulacion!F21)/Resultados_Simulacion!F21 -> 0.056393361 | I29: =Resultados_Simulacion!H29 -> 0.02429762 | J29: =(I29-Resultados_Simulacion!H21)/Resultados_Simulacion!H21 -> -0.12637959 | K29: =Resultados_Simulacion!I29 -> 0.017442508 | L29: =(K29-Resultados_Simulacion!I21)/Resultados_Simulacion!I21 -> -0.32545024
A30: 73000 | B30: 40% | C30: =Resultados_Simulacion!C30 -> 1.396031 | D30: =(C30-Resultados_Simulacion!C21)/Resultados_Simulacion!C21 -> 0 | E30: =Resultados_Simulacion!E30 -> 0.04061992 | F30: =(E30-Resultados_Simulacion!E21)/Resultados_Simulacion!E21 -> 0 | G30: =Resultados_Simulacion!F30 -> 46.010602 | H30: =(G30-Resultados_Simulacion!F21)/Resultados_Simulacion!F21 -> 0.064218408 | I30: =Resultados_Simulacion!H30 -> 0.02382853 | J30: =(I30-Resultados_Simulacion!H21)/Resultados_Simulacion!H21 -> -0.14324571 | K30: =Resultados_Simulacion!I30 -> 0.017215517 | L30: =(K30-Resultados_Simulacion!I21)/Resultados_Simulacion!I21 -> -0.3342286
A31: 73000 | B31: 45% | C31: =Resultados_Simulacion!C31 -> 1.396031 | D31: =(C31-Resultados_Simulacion!C21)/Resultados_Simulacion!C21 -> 0 | E31: =Resultados_Simulacion!E31 -> 0.04061992 | F31: =(E31-Resultados_Simulacion!E21)/Resultados_Simulacion!E21 -> 0 | G31: =Resultados_Simulacion!F31 -> 46.192795 | H31: =(G31-Resultados_Simulacion!F21)/Resultados_Simulacion!F21 -> 0.068432525 | I31: =Resultados_Simulacion!H31 -> 0.0224414 | J31: =(I31-Resultados_Simulacion!H21)/Resultados_Simulacion!H21 -> -0.19311994 | K31: =Resultados_Simulacion!I31 -> 0.01684928 | L31: =(K31-Resultados_Simulacion!I21)/Resultados_Simulacion!I21 -> -0.34839196
A32: 73000 | B32: 48% | C32: =Resultados_Simulacion!C32 -> 1.396031 | D32: =(C32-Resultados_Simulacion!C21)/Resultados_Simulacion!C21 -> 0 | E32: =Resultados_Simulacion!E32 -> 0.04061992 | F32: =(E32-Resultados_Simulacion!E21)/Resultados_Simulacion!E21 -> 0 | G32: =Resultados_Simulacion!F32 -> 46.050969 | H32: =(G32-Resultados_Simulacion!F21)/Resultados_Simulacion!F21 -> 0.065152109 | I32: =Resultados_Simulacion!H32 -> 0.02148545 | J32: =(I32-Resultados_Simulacion!H21)/Resultados_Simulacion!H21 -> -0.2274911 | K32: =Resultados_Simulacion!I32 -> 0.016696282 | L32: =(K32-Resultados_Simulacion!I21)/Resultados_Simulacion!I21 -> -0.35430882
A33: 73000 | B33: 50% | C33: =Resultados_Simulacion!C33 -> 1.396031 | D33: =(C33-Resultados_Simulacion!C21)/Resultados_Simulacion!C21 -> 0 | E33: =Resultados_Simulacion!E33 -> 0.04061992 | F33: =(E33-Resultados_Simulacion!E21)/Resultados_Simulacion!E21 -> 0 | G33: =Resultados_Simulacion!F33 -> 45.799911 | H33: =(G33-Resultados_Simulacion!F21)/Resultados_Simulacion!F21 -> 0.059345156 | I33: =Resultados_Simulacion!H33 -> 0.02119912 | J33: =(I33-Resultados_Simulacion!H21)/Resultados_Simulacion!H21 -> -0.23778609 | K33: =Resultados_Simulacion!I33 -> 0.016560086 | L33: =(K33-Resultados_Simulacion!I21)/Resultados_Simulacion!I21 -> -0.35957591
A34: 73000 | B34: 55% | C34: =Resultados_Simulacion!C34 -> 1.396031 | D34: =(C34-Resultados_Simulacion!C21)/Resultados_Simulacion!C21 -> 0 | E34: =Resultados_Simulacion!E34 -> 0.04061992 | F34: =(E34-Resultados_Simulacion!E21)/Resultados_Simulacion!E21 -> 0 | G34: =Resultados_Simulacion!F34 -> 44.698868 | H34: =(G34-Resultados_Simulacion!F21)/Resultados_Simulacion!F21 -> 0.03387821 | I34: =Resultados_Simulacion!H34 -> 0.02013338 | J34: =(I34-Resultados_Simulacion!H21)/Resultados_Simulacion!H21 -> -0.27610475 | K34: =Resultados_Simulacion!I34 -> 0.016347351 | L34: =(K34-Resultados_Simulacion!I21)/Resultados_Simulacion!I21 -> -0.36780296
A35: 73000 | B35: 57% | C35: =Resultados_Simulacion!C35 -> 1.396031 | D35: =(C35-Resultados_Simulacion!C21)/Resultados_Simulacion!C21 -> 0 | E35: =Resultados_Simulacion!E35 -> 0.04061992 | F35: =(E35-Resultados_Simulacion!E21)/Resultados_Simulacion!E21 -> 0 | G35: =Resultados_Simulacion!F35 -> 43.780976 | H35: =(G35-Resultados_Simulacion!F21)/Resultados_Simulacion!F21 -> 0.012647506 | I35: =Resultados_Simulacion!H35 -> 0.02005482 | J35: =(I35-Resultados_Simulacion!H21)/Resultados_Simulacion!H21 -> -0.27892938 | K35: =Resultados_Simulacion!I35 -> 0.016280798 | L35: =(K35-Resultados_Simulacion!I21)/Resultados_Simulacion!I21 -> -0.37037676
A36: 73000 | B36: 60% | C36: =Resultados_Simulacion!C36 -> 1.396031 | D36: =(C36-Resultados_Simulacion!C21)/Resultados_Simulacion!C21 -> 0 | E36: =Resultados_Simulacion!E36 -> 0.04061992 | F36: =(E36-Resultados_Simulacion!E21)/Resultados_Simulacion!E21 -> 0 | G36: =Resultados_Simulacion!F36 -> 43.234172 | H36: =(G36-Resultados_Simulacion!F21)/Resultados_Simulacion!F21 -> 0 | I36: =Resultados_Simulacion!H36 -> 0.02781256 | J36: =(I36-Resultados_Simulacion!H21)/Resultados_Simulacion!H21 -> 0 | K36: =Resultados_Simulacion!I36 -> 0.016246425 | L36: =(K36-Resultados_Simulacion!I21)/Resultados_Simulacion!I21 -> -0.37170605
A37: 73000 | B37: 65% | C37: =Resultados_Simulacion!C37 -> 1.396031 | D37: =(C37-Resultados_Simulacion!C21)/Resultados_Simulacion!C21 -> 0 | E37: =Resultados_Simulacion!E37 -> 0.04061992 | F37: =(E37-Resultados_Simulacion!E21)/Resultados_Simulacion!E21 -> 0 | G37: =Resultados_Simulacion!F37 -> 43.234172 | H37: =(G37-Resultados_Simulacion!F21)/Resultados_Simulacion!F21 -> 0 | I37: =Resultados_Simulacion!H37 -> 0.02781256 | J37: =(I37-Resultados_Simulacion!H21)/Resultados_Simulacion!H21 -> 0 | K37: =Resultados_Simulacion!I37 -> 0.016290942 | L37: =(K37-Resultados_Simulacion!I21)/Resultados_Simulacion!I21 -> -0.36998444
A38: 73000 | B38: 68% | C38: =Resultados_Simulacion!C38 -> 1.396031 | D38: =(C38-Resultados_Simulacion!C21)/Resultados_Simulacion!C21 -> 0 | E38: =Resultados_Simulacion!E38 -> 0.04061992 | F38: =(E38-Resultados_Simulacion!E21)/Resultados_Simulacion!E21 -> 0 | G38: =Resultados_Simulacion!F38 -> 43.234172 | H38: =(G38-Resultados_Simulacion!F21)/Resultados_Simulacion!F21 -> 0 | I38: =Resultados_Simulacion!H38 -> 0.02781256 | J38: =(I38-Resultados_Simulacion!H21)/Resultados_Simulacion!H21 -> 0 | K38: =Resultados_Simulacion!I38 -> 0.016385723 | L38: =(K38-Resultados_Simulacion!I21)/Resultados_Simulacion!I21 -> -0.36631901
A39: 73000 | B39: 70% | C39: =Resultados_Simulacion!C39 -> 1.396031 | D39: =(C39-Resultados_Simulacion!C21)/Resultados_Simulacion!C21 -> 0 | E39: =Resultados_Simulacion!E39 -> 0.04061992 | F39: =(E39-Resultados_Simulacion!E21)/Resultados_Simulacion!E21 -> 0 | G39: =Resultados_Simulacion!F39 -> 43.234172 | H39: =(G39-Resultados_Simulacion!F21)/Resultados_Simulacion!F21 -> 0 | I39: =Resultados_Simulacion!H39 -> 0.02781256 | J39: =(I39-Resultados_Simulacion!H21)/Resultados_Simulacion!H21 -> 0 | K39: =Resultados_Simulacion!I39 -> 0.016576516 | L39: =(K39-Resultados_Simulacion!I21)/Resultados_Simulacion!I21 -> -0.35894051
A40: 79000 | B40: Libre | C40: =Resultados_Simulacion!C40 -> 1.386712 | D40: =(C40-Resultados_Simulacion!C40)/Resultados_Simulacion!C40 -> 0 | E40: =Resultados_Simulacion!E40 -> 0.0388465 | F40: =(E40-Resultados_Simulacion!E40)/Resultados_Simulacion!E40 -> 0 | G40: =Resultados_Simulacion!F40 -> 45.913696 | H40: =(G40-Resultados_Simulacion!F40)/Resultados_Simulacion!F40 -> 0 | I40: =Resultados_Simulacion!H40 -> 0.02528263 | J40: =(I40-Resultados_Simulacion!H40)/Resultados_Simulacion!H40 -> 0 | K40: =Resultados_Simulacion!I40 -> 0.023353297 | L40: =(K40-Resultados_Simulacion!I40)/Resultados_Simulacion!I40 -> 0
...

Sheet Estadistica_por_Re
A1: Re | B1: Promedio %var Cl_max | C1: DesvEst %var Cl_max | D1: Rango %var Cl_max | E1: Máx |%var| Cl_max | F1: Promedio %var Cd@Clmax | G1: DesvEst %var Cd@Clmax | H1: Rango %var Cd@Clmax | I1: Máx |%var| Cd@Clmax | J1: Promedio %var Cl/Cd_max | K1: DesvEst %var Cl/Cd_max | L1: Rango %var Cl/Cd_max | M1: Máx |%var| Cl/Cd_max | N1: Promedio %var Cd@Cl=0.50 | O1: DesvEst %var Cd@Cl=0.50 | P1: Rango %var Cd@Cl=0.50 | Q1: Máx |%var| Cd@Cl=0.50
A2: 66000 | B2: =AVERAGE(Variacion_vs_Libre!D3,Variacion_vs_Libre!D4,Variacion_vs_Libre!D5,Variacion_vs_Libre!D6,Variacion_vs_Libre!D7,Variacion_vs_Libre!D8,Variacion_vs_Libre!D9,Variacion_vs_Libre!D10,Variacion_vs_Libre!D11,Variacion_vs_Libre!D12,Variacion_vs_Libre!D13,Variacion_vs_Libre!D14,Variacion_vs_Libre!D15,Variacion_vs_Libre!D16,Variacion_vs_Libre!D17,Variacion_vs_Libre!D18,Variacion_vs_Libre!D19,Variacion_vs_Libre!D20) -> -0.012228117 | C2: =STDEV(Variacion_vs_Libre!D3,Variacion_vs_Libre!D4,Variacion_vs_Libre!D5,Variacion_vs_Libre!D6,Variacion_vs_Libre!D7,Variacion_vs_Libre!D8,Variacion_vs_Libre!D9,Variacion_vs_Libre!D10,Variacion_vs_Libre!D11,Variacion_vs_Libre!D12,Variacion_vs_Libre!D13,Variacion_vs_Libre!D14,Variacion_vs_Libre!D15,Variacion_vs_Libre!D16,Variacion_vs_Libre!D17,Variacion_vs_Libre!D18,Variacion_vs_Libre!D19,Variacion_vs_Libre!D20) -> 0.035811158 | D2: =MAX(Variacion_vs_Libre!D3,Variacion_vs_Libre!D4,Variacion_vs_Libre!D5,Variacion_vs_Libre!D6,Variacion_vs_Libre!D7,Variacion_vs_Libre!D8,Variacion_vs_Libre!D9,Variacion_vs_Libre!D10,Variacion_vs_Libre!D11,Variacion_vs_Libre!D12,Variacion_vs_Libre!D13,Variacion_vs_Libre!D14,Variacion_vs_Libre!D15,Variacion_vs_Libre!D16,Variacion_vs_Libre!D17,Variacion_vs_Libre!D18,Variacion_vs_Libre!D19,Variacion_vs_Libre!D20)-MIN(Variacion_vs_Libre!D3,Variacion_vs_Libre!D4,Variacion_vs_Libre!D5,Variacion_vs_Libre!D6,Variacion_vs_Libre!D7,Variacion_vs_Libre!D8,Variacion_vs_Libre!D9,Variacion_vs_Libre!D10,Variacion_vs_Libre!D11,Variacion_vs_Libre!D12,Variacion_vs_Libre!D13,Variacion_vs_Libre!D14,Variacion_vs_Libre!D15,Variacion_vs_Libre!D16,Variacion_vs_Libre!D17,Variacion_vs_Libre!D18,Variacion_vs_Libre!D19,Variacion_vs_Libre!D20) -> 0.14341629 | E2: =MAX(MAX(Variacion_vs_Libre!D3,Variacion_vs_Libre!D4,Variacion_vs_Libre!D5,Variacion_vs_Libre!D6,Variacion_vs_Libre!D7,Variacion_vs_Libre!D8,Variacion_vs_Libre!D9,Variacion_vs_Libre!D10,Variacion_vs_Libre!D11,Variacion_vs_Libre!D12,Variacion_vs_Libre!D13,Variacion_vs_Libre!D14,Variacion_vs_Libre!D15,Variacion_vs_Libre!D16,Variacion_vs_Libre!D17,Variacion_vs_Libre!D18,Variacion_vs_Libre!D19,Variacion_vs_Libre!D20),-MIN(Variacion_vs_Libre!D3,Variacion_vs_Libre!D4,Variacion_vs_Libre!D5,Variacion_vs_Libre!D6,Variacion_vs_Libre!D7,Variacion_vs_Libre!D8,Variacion_vs_Libre!D9,Variacion_vs_Libre!D10,Variacion_vs_Libre!D11,Variacion_vs_Libre!D12,Variacion_vs_Libre!D13,Variacion_vs_Libre!D14,Variacion_vs_Libre!D15,Variacion_vs_Libre!D16,Variacion_vs_Libre!D17,Variacion_vs_Libre!D18,Variacion_vs_Libre!D19,Variacion_vs_Libre!D20)) -> 0.14341629 | F2: =AVERAGE(Variacion_vs_Libre!F3,Variacion_vs_Libre!F4,Variacion_vs_Libre!F5,Variacion_vs_Libre!F6,Variacion_vs_Libre!F7,Variacion_vs_Libre!F8,Variacion_vs_Libre!F9,Variacion_vs_Libre!F10,Variacion_vs_Libre!F11,Variacion_vs_Libre!F12,Variacion_vs_Libre!F13,Variacion_vs_Libre!F14,Variacion_vs_Libre!F15,Variacion_vs_Libre!F16,Variacion_vs_Libre!F17,Variacion_vs_Libre!F18,Variacion_vs_Libre!F19,Variacion_vs_Libre!F20) -> 0.073535884 | G2: =STDEV(Variacion_vs_Libre!F3,Variacion_vs_Libre!F4,Variacion_vs_Libre!F5,Variacion_vs_Libre!F6,Variacion_vs_Libre!F7,Variacion_vs_Libre!F8,Variacion_vs_Libre!F9,Variacion_vs_Libre!F10,Variacion_vs_Libre!F11,Variacion_vs_Libre!F12,Variacion_vs_Libre!F13,Variacion_vs_Libre!F14,Variacion_vs_Libre!F15,Variacion_vs_Libre!F16,Variacion_vs_Libre!F17,Variacion_vs_Libre!F18,Variacion_vs_Libre!F19,Variacion_vs_Libre!F20) -> 0.18839266 | H2: =MAX(Variacion_vs_Libre!F3,Variacion_vs_Libre!F4,Variacion_vs_Libre!F5,Variacion_vs_Libre!F6,Variacion_vs_Libre!F7,Variacion_vs_Libre!F8,Variacion_vs_Libre!F9,Variacion_vs_Libre!F10,Variacion_vs_Libre!F11,Variacion_vs_Libre!F12,Variacion_vs_Libre!F13,Variacion_vs_Libre!F14,Variacion_vs_Libre!F15,Variacion_vs_Libre!F16,Variacion_vs_Libre!F17,Variacion_vs_Libre!F18,Variacion_vs_Libre!F19,Variacion_vs_Libre!F20)-MIN(Variacion_vs_Libre!F3,Variacion_vs_Libre!F4,Variacion_vs_Libre!F5,Variacion_vs_Libre!F6,Variacion_vs_Libre!F7,Variacion_vs_Libre!F8,Variacion_vs_Libre!F9,Variacion_vs_Libre!F10,Variacion_vs_Libre!F11,Variacion_vs_Libre!F12,Variacion_vs_Libre!F13,Variacion_vs_Libre!F14,Variacion_vs_Libre!F15,Variacion_vs_Libre!F16,Variacion_vs_Libre!F17,Variacion_vs_Libre!F18,Variacion_vs_Libre!F19,Variacion_vs_Libre!F20) -> 0.65253865 | I2: =MAX(MAX(Variacion_vs_Libre!F3,Variacion_vs_Libre!F4,Variacion_vs_Libre!F5,Variacion_vs_Libre!F6,Variacion_vs_Libre!F7,Variacion_vs_Libre!F8,Variacion_vs_Libre!F9,Variacion_vs_Libre!F10,Variacion_vs_Libre!F11,Variacion_vs_Libre!F12,Variacion_vs_Libre!F13,Variacion_vs_Libre!F14,Variacion_vs_Libre!F15,Variacion_vs_Libre!F16,Variacion_vs_Libre!F17,Variacion_vs_Libre!F18,Variacion_vs_Libre!F19,Variacion_vs_Libre!F20),-MIN(Variacion_vs_Libre!F3,Variacion_vs_Libre!F4,Variacion_vs_Libre!F5,Variacion_vs_Libre!F6,Variacion_vs_Libre!F7,Variacion_vs_Libre!F8,Variacion_vs_Libre!F9,Variacion_vs_Libre!F10,Variacion_vs_Libre!F11,Variacion_vs_Libre!F12,Variacion_vs_Libre!F13,Variacion_vs_Libre!F14,Variacion_vs_Libre!F15,Variacion_vs_Libre!F16,Variacion_vs_Libre!F17,Variacion_vs_Libre!F18,Variacion_vs_Libre!F19,Variacion_vs_Libre!F20)) -> 0.65253865 | J2: =AVERAGE(Variacion_vs_Libre!H3,Variacion_vs_Libre!H4,Variacion_vs_Libre!H5,Variacion_vs_Libre!H6,Variacion_vs_Libre!H7,Variacion_vs_Libre!H8,Variacion_vs_Libre!H9,Variacion_vs_Libre!H10,Variacion_vs_Libre!H11,Variacion_vs_Libre!H12,Variacion_vs_Libre!H13,Variacion_vs_Libre!H14,Variacion_vs_Libre!H15,Variacion_vs_Libre!H16,Variacion_vs_Libre!H17,Variacion_vs_Libre!H18,Variacion_vs_Libre!H19,Variacion_vs_Libre!H20) -> 0.0066942163 | K2: =STDEV(Variacion_vs_Libre!H3,Variacion_vs_Libre!H4,Variacion_vs_Libre!H5,Variacion_vs_Libre!H6,Variacion_vs_Libre!H7,Variacion_vs_Libre!H8,Variacion_vs_Libre!H9,Variacion_vs_Libre!H10,Variacion_vs_Libre!H11,Variacion_vs_Libre!H12,Variacion_vs_Libre!H13,Variacion_vs_Libre!H14,Variacion_vs_Libre!H15,Variacion_vs_Libre!H16,Variacion_vs_Libre!H17,Variacion_vs_Libre!H18,Variacion_vs_Libre!H19,Variacion_vs_Libre!H20) -> 0.079169262 | L2: =MAX(Variacion_vs_Libre!H3,Variacion_vs_Libre!H4,Variacion_vs_Libre!H5,Variacion_vs_Libre!H6,Variacion_vs_Libre!H7,Variacion_vs_Libre!H8,Variacion_vs_Libre!H9,Variacion_vs_Libre!H10,Variacion_vs_Libre!H11,Variacion_vs_Libre!H12,Variacion_vs_Libre!H13,Variacion_vs_Libre!H14,Variacion_vs_Libre!H15,Variacion_vs_Libre!H16,Variacion_vs_Libre!H17,Variacion_vs_Libre!H18,Variacion_vs_Libre!H19,Variacion_vs_Libre!H20)-MIN(Variacion_vs_Libre!H3,Variacion_vs_Libre!H4,Variacion_vs_Libre!H5,Variacion_vs_Libre!H6,Variacion_vs_Libre!H7,Variacion_vs_Libre!H8,Variacion_vs_Libre!H9,Variacion_vs_Libre!H10,Variacion_vs_Libre!H11,Variacion_vs_Libre!H12,Variacion_vs_Libre!H13,Variacion_vs_Libre!H14,Variacion_vs_Libre!H15,Variacion_vs_Libre!H16,Variacion_vs_Libre!H17,Variacion_vs_Libre!H18,Variacion_vs_Libre!H19,Variacion_vs_Libre!H20) -> 0.26913679 | M2: =MAX(MAX(Variacion_vs_Libre!H3,Variacion_vs_Libre!H4,Variacion_vs_Libre!H5,Variacion_vs_Libre!H6,Variacion_vs_Libre!H7,Variacion_vs_Libre!H8,Variacion_vs_Libre!H9,Variacion_vs_Libre!H10,Variacion_vs_Libre!H11,Variacion_vs_Libre!H12,Variacion_vs_Libre!H13,Variacion_vs_Libre!H14,Variacion_vs_Libre!H15,Variacion_vs_Libre!H16,Variacion_vs_Libre!H17,Variacion_vs_Libre!H18,Variacion_vs_Libre!H19,Variacion_vs_Libre!H20),-MIN(Variacion_vs_Libre!H3,Variacion_vs_Libre!H4,Variacion_vs_Libre!H5,Variacion_vs_Libre!H6,Variacion_vs_Libre!H7,Variacion_vs_Libre!H8,Variacion_vs_Libre!H9,Variacion_vs_Libre!H10,Variacion_vs_Libre!H11,Variacion_vs_Libre!H12,Variacion_vs_Libre!H13,Variacion_vs_Libre!H14,Variacion_vs_Libre!H15,Variacion_vs_Libre!H16,Variacion_vs_Libre!H17,Variacion_vs_Libre!H18,Variacion_vs_Libre!H19,Variacion_vs_Libre!H20)) -> 0.17713679 | N2: =AVERAGE(Variacion_vs_Libre!L3,Variacion_vs_Libre!L4,Variacion_vs_Libre!L5,Variacion_vs_Libre!L6,Variacion_vs_Libre!L7,Variacion_vs_Libre!L8,Variacion_vs_Libre!L9,Variacion_vs_Libre!L10,Variacion_vs_Libre!L11,Variacion_vs_Libre!L12,Variacion_vs_Libre!L13,Variacion_vs_Libre!L14,Variacion_vs_Libre!L15,Variacion_vs_Libre!L16,Variacion_vs_Libre!L17,Variacion_vs_Libre!L18,Variacion_vs_Libre!L19,Variacion_vs_Libre!L20) -> -0.35141415 | O2: =STDEV(Variacion_vs_Libre!L3,Variacion_vs_Libre!L4,Variacion_vs_Libre!L5,Variacion_vs_Libre!L6,Variacion_vs_Libre!L7,Variacion_vs_Libre!L8,Variacion_vs_Libre!L9,Variacion_vs_Libre!L10,Variacion_vs_Libre!L11,Variacion_vs_Libre!L12,Variacion_vs_Libre!L13,Variacion_vs_Libre!L14,Variacion_vs_Libre!L15,Variacion_vs_Libre!L16,Variacion_vs_Libre!L17,Variacion_vs_Libre!L18,Variacion_vs_Libre!L19,Variacion_vs_Libre!L20) -> 0.049012332 | P2: =MAX(Variacion_vs_Libre!L3,Variacion_vs_Libre!L4,Variacion_vs_Libre!L5,Variacion_vs_Libre!L6,Variacion_vs_Libre!L7,Variacion_vs_Libre!L8,Variacion_vs_Libre!L9,Variacion_vs_Libre!L10,Variacion_vs_Libre!L11,Variacion_vs_Libre!L12,Variacion_vs_Libre!L13,Variacion_vs_Libre!L14,Variacion_vs_Libre!L15,Variacion_vs_Libre!L16,Variacion_vs_Libre!L17,Variacion_vs_Libre!L18,Variacion_vs_Libre!L19,Variacion_vs_Libre!L20)-MIN(Variacion_vs_Libre!L3,Variacion_vs_Libre!L4,Variacion_vs_Libre!L5,Variacion_vs_Libre!L6,Variacion_vs_Libre!L7,Variacion_vs_Libre!L8,Variacion_vs_Libre!L9,Variacion_vs_Libre!L10,Variacion_vs_Libre!L11,Variacion_vs_Libre!L12,Variacion_vs_Libre!L13,Variacion_vs_Libre!L14,Variacion_vs_Libre!L15,Variacion_vs_Libre!L16,Variacion_vs_Libre!L17,Variacion_vs_Libre!L18,Variacion_vs_Libre!L19,Variacion_vs_Libre!L20) -> 0.14549675 | Q2: =MAX(MAX(Variacion_vs_Libre!L3,Variacion_vs_Libre!L4,Variacion_vs_Libre!L5,Variacion_vs_Libre!L6,Variacion_vs_Libre!L7,Variacion_vs_Libre!L8,Variacion_vs_Libre!L9,Variacion_vs_Libre!L10,Variacion_vs_Libre!L11,Variacion_vs_Libre!L12,Variacion_vs_Libre!L13,Variacion_vs_Libre!L14,Variacion_vs_Libre!L15,Variacion_vs_Libre!L16,Variacion_vs_Libre!L17,Variacion_vs_Libre!L18,Variacion_vs_Libre!L19,Variacion_vs_Libre!L20),-MIN(Variacion_vs_Libre!L3,Variacion_vs_Libre!L4,Variacion_vs_Libre!L5,Variacion_vs_Libre!L6,Variacion_vs_Libre!L7,Variacion_vs_Libre!L8,Variacion_vs_Libre!L9,Variacion_vs_Libre!L10,Variacion_vs_Libre!L11,Variacion_vs_Libre!L12,Variacion_vs_Libre!L13,Variacion_vs_Libre!L14,Variacion_vs_Libre!L15,Variacion_vs_Libre!L16,Variacion_vs_Libre!L17,Variacion_vs_Libre!L18,Variacion_vs_Libre!L19,Variacion_vs_Libre!L20)) -> 0.39809724
A3: 73000 | B3: =AVERAGE(Variacion_vs_Libre!D22,Variacion_vs_Libre!D23,Variacion_vs_Libre!D24,Variacion_vs_Libre!D25,Variacion_vs_Libre!D26,Variacion_vs_Libre!D27,Variacion_vs_Libre!D28,Variacion_vs_Libre!D29,Variacion_vs_Libre!D30,Variacion_vs_Libre!D31,Variacion_vs_Libre!D32,Variacion_vs_Libre!D33,Variacion_vs_Libre!D34,Variacion_vs_Libre!D35,Variacion_vs_Libre!D36,Variacion_vs_Libre!D37,Variacion_vs_Libre!D38,Variacion_vs_Libre!D39) -> -0.01016266 | C3: =STDEV(Variacion_vs_Libre!D22,Variacion_vs_Libre!D23,Variacion_vs_Libre!D24,Variacion_vs_Libre!D25,Variacion_vs_Libre!D26,Variacion_vs_Libre!D27,Variacion_vs_Libre!D28,Variacion_vs_Libre!D29,Variacion_vs_Libre!D30,Variacion_vs_Libre!D31,Variacion_vs_Libre!D32,Variacion_vs_Libre!D33,Variacion_vs_Libre!D34,Variacion_vs_Libre!D35,Variacion_vs_Libre!D36,Variacion_vs_Libre!D37,Variacion_vs_Libre!D38,Variacion_vs_Libre!D39) -> 0.029529814 | D3: =MAX(Variacion_vs_Libre!D22,Variacion_vs_Libre!D23,Variacion_vs_Libre!D24,Variacion_vs_Libre!D25,Variacion_vs_Libre!D26,Variacion_vs_Libre!D27,Variacion_vs_Libre!D28,Variacion_vs_Libre!D29,Variacion_vs_Libre!D30,Variacion_vs_Libre!D31,Variacion_vs_Libre!D32,Variacion_vs_Libre!D33,Variacion_vs_Libre!D34,Variacion_vs_Libre!D35,Variacion_vs_Libre!D36,Variacion_vs_Libre!D37,Variacion_vs_Libre!D38,Variacion_vs_Libre!D39)-MIN(Variacion_vs_Libre!D22,Variacion_vs_Libre!D23,Variacion_vs_Libre!D24,Variacion_vs_Libre!D25,Variacion_vs_Libre!D26,Variacion_vs_Libre!D27,Variacion_vs_Libre!D28,Variacion_vs_Libre!D29,Variacion_vs_Libre!D30,Variacion_vs_Libre!D31,Variacion_vs_Libre!D32,Variacion_vs_Libre!D33,Variacion_vs_Libre!D34,Variacion_vs_Libre!D35,Variacion_vs_Libre!D36,Variacion_vs_Libre!D37,Variacion_vs_Libre!D38,Variacion_vs_Libre!D39) -> 0.11710127 | E3: =MAX(MAX(Variacion_vs_Libre!D22,Variacion_vs_Libre!D23,Variacion_vs_Libre!D24,Variacion_vs_Libre!D25,Variacion_vs_Libre!D26,Variacion_vs_Libre!D27,Variacion_vs_Libre!D28,Variacion_vs_Libre!D29,Variacion_vs_Libre!D30,Variacion_vs_Libre!D31,Variacion_vs_Libre!D32,Variacion_vs_Libre!D33,Variacion_vs_Libre!D34,Variacion_vs_Libre!D35,Variacion_vs_Libre!D36,Variacion_vs_Libre!D37,Variacion_vs_Libre!D38,Variacion_vs_Libre!D39),-MIN(Variacion_vs_Libre!D22,Variacion_vs_Libre!D23,Variacion_vs_Libre!D24,Variacion_vs_Libre!D25,Variacion_vs_Libre!D26,Variacion_vs_Libre!D27,Variacion_vs_Libre!D28,Variacion_vs_Libre!D29,Variacion_vs_Libre!D30,Variacion_vs_Libre!D31,Variacion_vs_Libre!D32,Variacion_vs_Libre!D33,Variacion_vs_Libre!D34,Variacion_vs_Libre!D35,Variacion_vs_Libre!D36,Variacion_vs_Libre!D37,Variacion_vs_Libre!D38,Variacion_vs_Libre!D39)) -> 0.11710127 | F3: =AVERAGE(Variacion_vs_Libre!F22,Variacion_vs_Libre!F23,Variacion_vs_Libre!F24,Variacion_vs_Libre!F25,Variacion_vs_Libre!F26,Variacion_vs_Libre!F27,Variacion_vs_Libre!F28,Variacion_vs_Libre!F29,Variacion_vs_Libre!F30,Variacion_vs_Libre!F31,Variacion_vs_Libre!F32,Variacion_vs_Libre!F33,Variacion_vs_Libre!F34,Variacion_vs_Libre!F35,Variacion_vs_Libre!F36,Variacion_vs_Libre!F37,Variacion_vs_Libre!F38,Variacion_vs_Libre!F39) -> 0.073028592 | G3: =STDEV(Variacion_vs_Libre!F22,Variacion_vs_Libre!F23,Variacion_vs_Libre!F24,Variacion_vs_Libre!F25,Variacion_vs_Libre!F26,Variacion_vs_Libre!F27,Variacion_vs_Libre!F28,Variacion_vs_Libre!F29,Variacion_vs_Libre!F30,Variacion_vs_Libre!F31,Variacion_vs_Libre!F32,Variacion_vs_Libre!F33,Variacion_vs_Libre!F34,Variacion_vs_Libre!F35,Variacion_vs_Libre!F36,Variacion_vs_Libre!F37,Variacion_vs_Libre!F38,Variacion_vs_Libre!F39) -> 0.18334735 | H3: =MAX(Variacion_vs_Libre!F22,Variacion_vs_Libre!F23,Variacion_vs_Libre!F24,Variacion_vs_Libre!F25,Variacion_vs_Libre!F26,Variacion_vs_Libre!F27,Variacion_vs_Libre!F28,Variacion_vs_Libre!F29,Variacion_vs_Libre!F30,Variacion_vs_Libre!F31,Variacion_vs_Libre!F32,Variacion_vs_Libre!F33,Variacion_vs_Libre!F34,Variacion_vs_Libre!F35,Variacion_vs_Libre!F36,Variacion_vs_Libre!F37,Variacion_vs_Libre!F38,Variacion_vs_Libre!F39)-MIN(Variacion_vs_Libre!F22,Variacion_vs_Libre!F23,Variacion_vs_Libre!F24,Variacion_vs_Libre!F25,Variacion_vs_Libre!F26,Variacion_vs_Libre!F27,Variacion_vs_Libre!F28,Variacion_vs_Libre!F29,Variacion_vs_Libre!F30,Variacion_vs_Libre!F31,Variacion_vs_Libre!F32,Variacion_vs_Libre!F33,Variacion_vs_Libre!F34,Variacion_vs_Libre!F35,Variacion_vs_Libre!F36,Variacion_vs_Libre!F37,Variacion_vs_Libre!F38,Variacion_vs_Libre!F39) -> 0.62258247 | I3: =MAX(MAX(Variacion_vs_Libre!F22,Variacion_vs_Libre!F23,Variacion_vs_Libre!F24,Variacion_vs_Libre!F25,Variacion_vs_Libre!F26,Variacion_vs_Libre!F27,Variacion_vs_Libre!F28,Variacion_vs_Libre!F29,Variacion_vs_Libre!F30,Variacion_vs_Libre!F31,Variacion_vs_Libre!F32,Variacion_vs_Libre!F33,Variacion_vs_Libre!F34,Variacion_vs_Libre!F35,Variacion_vs_Libre!F36,Variacion_vs_Libre!F37,Variacion_vs_Libre!F38,Variacion_vs_Libre!F39),-MIN(Variacion_vs_Libre!F22,Variacion_vs_Libre!F23,Variacion_vs_Libre!F24,Variacion_vs_Libre!F25,Variacion_vs_Libre!F26,Variacion_vs_Libre!F27,Variacion_vs_Libre!F28,Variacion_vs_Libre!F29,Variacion_vs_Libre!F30,Variacion_vs_Libre!F31,Variacion_vs_Libre!F32,Variacion_vs_Libre!F33,Variacion_vs_Libre!F34,Variacion_vs_Libre!F35,Variacion_vs_Libre!F36,Variacion_vs_Libre!F37,Variacion_vs_Libre!F38,Variacion_vs_Libre!F39)) -> 0.62258247 | J3: =AVERAGE(Variacion_vs_Libre!H22,Variacion_vs_Libre!H23,Variacion_vs_Libre!H24,Variacion_vs_Libre!H25,Variacion_vs_Libre!H26,Variacion_vs_Libre!H27,Variacion_vs_Libre!H28,Variacion_vs_Libre!H29,Variacion_vs_Libre!H30,Variacion_vs_Libre!H31,Variacion_vs_Libre!H32,Variacion_vs_Libre!H33,Variacion_vs_Libre!H34,Variacion_vs_Libre!H35,Variacion_vs_Libre!H36,Variacion_vs_Libre!H37,Variacion_vs_Libre!H38,Variacion_vs_Libre!H39) -> -0.0078895982 | K3: =STDEV(Variacion_vs_Libre!H22,Variacion_vs_Libre!H23,Variacion_vs_Libre!H24,Variacion_vs_Libre!H25,Variacion_vs_Libre!H26,Variacion_vs_Libre!H27,Variacion_vs_Libre!H28,Variacion_vs_Libre!H29,Variacion_vs_Libre!H30,Variacion_vs_Libre!H31,Variacion_vs_Libre!H32,Variacion_vs_Libre!H33,Variacion_vs_Libre!H34,Variacion_vs_Libre!H35,Variacion_vs_Libre!H36,Variacion_vs_Libre!H37,Variacion_vs_Libre!H38,Variacion_vs_Libre!H39) -> 0.076160998 | L3: =MAX(Variacion_vs_Libre!H22,Variacion_vs_Libre!H23,Variacion_vs_Libre!H24,Variacion_vs_Libre!H25,Variacion_vs_Libre!H26,Variacion_vs_Libre!H27,Variacion_vs_Libre!H28,Variacion_vs_Libre!H29,Variacion_vs_Libre!H30,Variacion_vs_Libre!H31,Variacion_vs_Libre!H32,Variacion_vs_Libre!H33,Variacion_vs_Libre!H34,Variacion_vs_Libre!H35,Variacion_vs_Libre!H36,Variacion_vs_Libre!H37,Variacion_vs_Libre!H38,Variacion_vs_Libre!H39)-MIN(Variacion_vs_Libre!H22,Variacion_vs_Libre!H23,Variacion_vs_Libre!H24,Variacion_vs_Libre!H25,Variacion_vs_Libre!H26,Variacion_vs_Libre!H27,Variacion_vs_Libre!H28,Variacion_vs_Libre!H29,Variacion_vs_Libre!H30,Variacion_vs_Libre!H31,Variacion_vs_Libre!H32,Variacion_vs_Libre!H33,Variacion_vs_Libre!H34,Variacion_vs_Libre!H35,Variacion_vs_Libre!H36,Variacion_vs_Libre!H37,Variacion_vs_Libre!H38,Variacion_vs_Libre!H39) -> 0.26075692 | M3: =MAX(MAX(Variacion_vs_Libre!H22,Variacion_vs_Libre!H23,Variacion_vs_Libre!H24,Variacion_vs_Libre!H25,Variacion_vs_Libre!H26,Variacion_vs_Libre!H27,Variacion_vs_Libre!H28,Variacion_vs_Libre!H29,Variacion_vs_Libre!H30,Variacion_vs_Libre!H31,Variacion_vs_Libre!H32,Variacion_vs_Libre!H33,Variacion_vs_Libre!H34,Variacion_vs_Libre!H35,Variacion_vs_Libre!H36,Variacion_vs_Libre!H37,Variacion_vs_Libre!H38,Variacion_vs_Libre!H39),-MIN(Variacion_vs_Libre!H22,Variacion_vs_Libre!H23,Variacion_vs_Libre!H24,Variacion_vs_Libre!H25,Variacion_vs_Libre!H26,Variacion_vs_Libre!H27,Variacion_vs_Libre!H28,Variacion_vs_Libre!H29,Variacion_vs_Libre!H30,Variacion_vs_Libre!H31,Variacion_vs_Libre!H32,Variacion_vs_Libre!H33,Variacion_vs_Libre!H34,Variacion_vs_Libre!H35,Variacion_vs_Libre!H36,Variacion_vs_Libre!H37,Variacion_vs_Libre!H38,Variacion_vs_Libre!H39)) -> 0.1923244 | N3: =AVERAGE(Variacion_vs_Libre!L22,Variacion_vs_Libre!L23,Variacion_vs_Libre!L24,Variacion_vs_Libre!L25,Variacion_vs_Libre!L26,Variacion_vs_Libre!L27,Variacion_vs_Libre!L28,Variacion_vs_Libre!L29,Variacion_vs_Libre!L30,Variacion_vs_Libre!L31,Variacion_vs_Libre!L32,Variacion_vs_Libre!L33,Variacion_vs_Libre!L34,Variacion_vs_Libre!L35,Variacion_vs_Libre!L36,Variacion_vs_Libre!L37,Variacion_vs_Libre!L38,Variacion_vs_Libre!L39) -> -0.31993828 | O3: =STDEV(Variacion_vs_Libre!L22,Variacion_vs_Libre!L23,Variacion_vs_Libre!L24,Variacion_vs_Libre!L25,Variacion_vs_Libre!L26,Variacion_vs_Libre!L27,Variacion_vs_Libre!L28,Variacion_vs_Libre!L29,Variacion_vs_Libre!L30,Variacion_vs_Libre!L31,Variacion_vs_Libre!L32,Variacion_vs_Libre!L33,Variacion_vs_Libre!L34,Variacion_vs_Libre!L35,Variacion_vs_Libre!L36,Variacion_vs_Libre!L37,Variacion_vs_Libre!L38,Variacion_vs_Libre!L39) -> 0.053842301 | P3: =MAX(Variacion_vs_Libre!L22,Variacion_vs_Libre!L23,Variacion_vs_Libre!L24,Variacion_vs_Libre!L25,Variacion_vs_Libre!L26,Variacion_vs_Libre!L27,Variacion_vs_Libre!L28,Variacion_vs_Libre!L29,Variacion_vs_Libre!L30,Variacion_vs_Libre!L31,Variacion_vs_Libre!L32,Variacion_vs_Libre!L33,Variacion_vs_Libre!L34,Variacion_vs_Libre!L35,Variacion_vs_Libre!L36,Variacion_vs_Libre!L37,Variacion_vs_Libre!L38,Variacion_vs_Libre!L39)-MIN(Variacion_vs_Libre!L22,Variacion_vs_Libre!L23,Variacion_vs_Libre!L24,Variacion_vs_Libre!L25,Variacion_vs_Libre!L26,Variacion_vs_Libre!L27,Variacion_vs_Libre!L28,Variacion_vs_Libre!L29,Variacion_vs_Libre!L30,Variacion_vs_Libre!L31,Variacion_vs_Libre!L32,Variacion_vs_Libre!L33,Variacion_vs_Libre!L34,Variacion_vs_Libre!L35,Variacion_vs_Libre!L36,Variacion_vs_Libre!L37,Variacion_vs_Libre!L38,Variacion_vs_Libre!L39) -> 0.15903277 | Q3: =MAX(MAX(Variacion_vs_Libre!L22,Variacion_vs_Libre!L23,Variacion_vs_Libre!L24,Variacion_vs_Libre!L25,Variacion_vs_Libre!L26,Variacion_vs_Libre!L27,Variacion_vs_Libre!L28,Variacion_vs_Libre!L29,Variacion_vs_Libre!L30,Variacion_vs_Libre!L31,Variacion_vs_Libre!L32,Variacion_vs_Libre!L33,Variacion_vs_Libre!L34,Variacion_vs_Libre!L35,Variacion_vs_Libre!L36,Variacion_vs_Libre!L37,Variacion_vs_Libre!L38,Variacion_vs_Libre!L39),-MIN(Variacion_vs_Libre!L22,Variacion_vs_Libre!L23,Variacion_vs_Libre!L24,Variacion_vs_Libre!L25,Variacion_vs_Libre!L26,Variacion_vs_Libre!L27,Variacion_vs_Libre!L28,Variacion_vs_Libre!L29,Variacion_vs_Libre!L30,Variacion_vs_Libre!L31,Variacion_vs_Libre!L32,Variacion_vs_Libre!L33,Variacion_vs_Libre!L34,Variacion_vs_Libre!L35,Variacion_vs_Libre!L36,Variacion_vs_Libre!L37,Variacion_vs_Libre!L38,Variacion_vs_Libre!L39)) -> 0.37170605
